<?xml version="1.0"?>
        <robot name="phylax" xmlns:xacro="http://ros.org/wiki/xacro">

        <xacro:include filename="$(find phylax_description)/urdf/phylax_base.gazebo.xacro" />
        <xacro:property name="PI" value="3.1415926535897931" />

        <xacro:property name="chassis_length" value="0.380" />
        <xacro:property name="chassis_width" value="0.310" />
        <xacro:property name="chassis_height" value="0.184" />

        <xacro:property name="wheel_radius" value="0.065" />
        <xacro:property name="wheel_width" value="0.060" />

        <link name="base_footprint">
                <visual>
                        <geometry>
                                <box size="0.38 0.310 0.000001"/>
                        </geometry>
                        <material name="grey">
                                <color rgba="0.5 0.5 0.5 0.5"/>
                        </material>
                </visual>
        </link>

        <link name="base_link">
                <collision>
                        <origin xyz="0 0 0.02" rpy="0 0 0"/>
                        <geometry>
                                <box size="0.37 0.165 0.08"/>
                        </geometry>
                </collision>
                <visual>
                        <origin xyz="0.0 0.0002 -0.018" rpy="${PI/2} 0 0"/>
                        <geometry>
                                <mesh filename="package://phylax_description/meshes/wild_thumper_6wd_chassis.stl" scale="0.001 0.001 0.001" />
                        </geometry>
                </visual>
                <inertial>
                        <origin xyz="0.00 0 -0.02" rpy="0 0 0"/>
                        <mass value="1"/>
                        <inertia ixx="1.0" ixy="0.0" ixz="0.0" iyy="1.0" iyz="0.0" izz="1.0"/>
                </inertial>
        </link>
        
        <link name="mounting_plate">
                <visual>
                        <origin xyz="0.0 0 -0.078" rpy="${PI/2} 0 0"/>
                        <geometry>
                                <mesh filename="package://phylax_description/meshes/wild_thumper_6wd_top.stl" scale="0.001 0.001 0.001" />
                        </geometry>
                </visual>                
                <collision>
                        <origin xyz="0 0 -0.015" rpy="0 0 0"/>
                        <geometry>
                                <box size="0.38 0.12 0.034"/>
                        </geometry>
                </collision>

        </link>
        <joint name="base_link_joint" type="fixed">
                <parent link="base_footprint"/>
                <child link="base_link"/>
                <origin xyz="0.0 0.0 0.062" rpy="0 0 0"/>
        </joint>
  
        <joint name="mounting_plate_joint" type="fixed">
                <parent link="base_link"/>
                <child link="mounting_plate"/>
                <origin xyz="0.0 0.0 0.06" rpy="0 0 0"/>
        </joint>
  
        <xacro:macro name="wheel" params="pos side xyz rpy xyzi rpyi cy">   
                <link name="${pos}_${side}_wheel">
                        <visual>
                                <origin xyz="${xyz}" rpy="${rpy}"/>
                                <geometry>
                                        <mesh filename="package://phylax_description/meshes/wild_thumper_6wd_wheel.stl" scale="0.001 0.001 0.001"/>
                                </geometry>
                        </visual>
                        <collision>
                                <origin xyz="0 ${cy} 0" rpy="${PI/2} 0 0"/>
                                <geometry>
                                        <cylinder radius="0.06" length="0.062"/>
                                </geometry>
                        </collision>
                        <inertial>
                                <origin xyz="0 0 0" rpy="0 0 0"/>
                                <mass value="0.1"/>
                                <inertia ixx="0.005" ixy="0" ixz="0" iyy="0.005" iyz="0" izz="0.005"/>
                        </inertial>
                </link>

                <gazebo reference="${pos}_${side}_wheel">
                        <mu1 value="1.0"/>
                        <mu2 value="1.0"/>
                        <kp value="1000000.0" />
                        <kd value="1.0" />
                        <fdir1 value="1 0 0"/>
                </gazebo>

                <joint name="${pos}_${side}_wheel_joint" type="continuous">
                        <parent link="base_link"/>
                        <child link="${pos}_${side}_wheel"/>
                        <axis xyz="0 1 0"/>
                        <origin xyz="${xyzi}" rpy="${rpyi}"/>
                </joint>

                <transmission name="${pos}_${side}_wheel_trans" type="SimpleTransmission">
                        <type>transmission_interface/SimpleTransmission</type>
                        <joint name="${pos}_${side}_wheel_joint">
                                <hardwareInterface>hardware_interface/VelocityJointInterface</hardwareInterface>
                        </joint>
                        <actuator name="{pos}_${side}_wheel_motor">
                                <mechanicalReduction>1</mechanicalReduction>
                        </actuator>
                </transmission>
        </xacro:macro>
  
        <xacro:wheel pos="front" side="left"  xyz="-0.15 -0.08 -0.02" rpy="${PI/2} 0 0" xyzi="0.15 0.08 0.0" rpyi="0 0 0" cy="0.038"/>
        <xacro:wheel pos="front" side="right" xyz="-0.15 0.08 0.02" rpy="${-PI/2} 0 0" xyzi="0.15 -0.08 0.0" rpyi="0 0 0" cy="-0.038"/>
        <xacro:wheel pos="center" side="left"  xyz="-0.15 -0.08 -0.02" rpy="${PI/2} 0 0"  xyzi="0.0 0.08 0.0" rpyi="0 0 0" cy="0.038"/>
        <xacro:wheel pos="center" side="right" xyz="-0.15 0.08 0.02" rpy="${-PI/2} 0 0"  xyzi="0.0 -0.08 0.0" rpyi="0 0 0" cy="-0.038"/>
        <xacro:wheel pos="rear" side="left"  xyz="-0.15 -0.08 -0.02" rpy="${PI/2} 0 0"  xyzi="-0.15 0.08 0.0" rpyi="0 0 0" cy="0.038"/>
        <xacro:wheel pos="rear" side="right" xyz="-0.15 0.08 0.02" rpy="${-PI/2} 0 0" xyzi="-0.15 -0.08 0.0" rpyi="0 0 0" cy="-0.038"/>      
 </robot>

